[2024-10-14T05:10:38.579+0000] {local_task_job_runner.py:123} INFO - ::group::Pre task execution logs
[2024-10-14T05:10:38.740+0000] {taskinstance.py:2612} INFO - Dependencies all met for dep_context=non-requeueable deps ti=<TaskInstance: eia_data_pipeline.fetch_api1_data scheduled__2024-10-13T00:00:00+00:00 [queued]>
[2024-10-14T05:10:38.810+0000] {taskinstance.py:2612} INFO - Dependencies all met for dep_context=requeueable deps ti=<TaskInstance: eia_data_pipeline.fetch_api1_data scheduled__2024-10-13T00:00:00+00:00 [queued]>
[2024-10-14T05:10:38.815+0000] {taskinstance.py:2865} INFO - Starting attempt 1 of 2
[2024-10-14T05:10:39.099+0000] {taskinstance.py:2888} INFO - Executing <Task(PythonOperator): fetch_api1_data> on 2024-10-13 00:00:00+00:00
[2024-10-14T05:10:39.513+0000] {standard_task_runner.py:104} INFO - Running: ['***', 'tasks', 'run', 'eia_data_pipeline', 'fetch_api1_data', 'scheduled__2024-10-13T00:00:00+00:00', '--job-id', '35', '--raw', '--subdir', 'DAGS_FOLDER/new_dag.py', '--cfg-path', '/tmp/tmpd0lvyr21']
[2024-10-14T05:10:39.550+0000] {standard_task_runner.py:105} INFO - Job 35: Subtask fetch_api1_data
[2024-10-14T05:10:39.436+0000] {warnings.py:112} WARNING - /home/***/.local/lib/python3.12/site-packages/***/task/task_runner/standard_task_runner.py:70: DeprecationWarning: This process (pid=85) is multi-threaded, use of fork() may lead to deadlocks in the child.
  pid = os.fork()

[2024-10-14T05:10:39.585+0000] {standard_task_runner.py:72} INFO - Started process 107 to run task
[2024-10-14T05:10:40.554+0000] {task_command.py:467} INFO - Running <TaskInstance: eia_data_pipeline.fetch_api1_data scheduled__2024-10-13T00:00:00+00:00 [running]> on host c463a51db3fc
[2024-10-14T05:10:41.547+0000] {taskinstance.py:3131} INFO - Exporting env vars: AIRFLOW_CTX_DAG_OWNER='***' AIRFLOW_CTX_DAG_ID='eia_data_pipeline' AIRFLOW_CTX_TASK_ID='fetch_api1_data' AIRFLOW_CTX_EXECUTION_DATE='2024-10-13T00:00:00+00:00' AIRFLOW_CTX_TRY_NUMBER='1' AIRFLOW_CTX_DAG_RUN_ID='scheduled__2024-10-13T00:00:00+00:00'
[2024-10-14T05:10:41.560+0000] {logging_mixin.py:190} INFO - Task instance is in running state
[2024-10-14T05:10:41.566+0000] {logging_mixin.py:190} INFO -  Previous state of the Task instance: queued
[2024-10-14T05:10:41.579+0000] {logging_mixin.py:190} INFO - Current task name:fetch_api1_data state:running start_date:2024-10-14 05:10:38.751645+00:00
[2024-10-14T05:10:41.589+0000] {logging_mixin.py:190} INFO - Dag name:eia_data_pipeline and current dag run status:running
[2024-10-14T05:10:41.597+0000] {taskinstance.py:731} INFO - ::endgroup::
[2024-10-14T05:10:51.153+0000] {taskinstance.py:3310} ERROR - Task failed with exception
Traceback (most recent call last):
  File "/home/airflow/.local/lib/python3.12/site-packages/sqlalchemy/engine/base.py", line 1910, in _execute_context
    self.dialect.do_execute(
  File "/home/airflow/.local/lib/python3.12/site-packages/sqlalchemy/engine/default.py", line 736, in do_execute
    cursor.execute(statement, parameters)
  File "/home/airflow/.local/lib/python3.12/site-packages/pymysql/cursors.py", line 153, in execute
    result = self._query(query)
             ^^^^^^^^^^^^^^^^^^
  File "/home/airflow/.local/lib/python3.12/site-packages/pymysql/cursors.py", line 322, in _query
    conn.query(q)
  File "/home/airflow/.local/lib/python3.12/site-packages/pymysql/connections.py", line 563, in query
    self._affected_rows = self._read_query_result(unbuffered=unbuffered)
                          ^^^^^^^^^^^^^^^^^^^^^^^^^^^^^^^^^^^^^^^^^^^^^^
  File "/home/airflow/.local/lib/python3.12/site-packages/pymysql/connections.py", line 825, in _read_query_result
    result.read()
  File "/home/airflow/.local/lib/python3.12/site-packages/pymysql/connections.py", line 1199, in read
    first_packet = self.connection._read_packet()
                   ^^^^^^^^^^^^^^^^^^^^^^^^^^^^^^
  File "/home/airflow/.local/lib/python3.12/site-packages/pymysql/connections.py", line 775, in _read_packet
    packet.raise_for_error()
  File "/home/airflow/.local/lib/python3.12/site-packages/pymysql/protocol.py", line 219, in raise_for_error
    err.raise_mysql_exception(self._data)
  File "/home/airflow/.local/lib/python3.12/site-packages/pymysql/err.py", line 150, in raise_mysql_exception
    raise errorclass(errno, errval)
pymysql.err.ProgrammingError: (1146, "Table 'eia.co2_emission' doesn't exist")

The above exception was the direct cause of the following exception:

Traceback (most recent call last):
  File "/home/airflow/.local/lib/python3.12/site-packages/sqlalchemy/dialects/mysql/base.py", line 3220, in _show_create_table
    ).exec_driver_sql(st)
      ^^^^^^^^^^^^^^^^^^^
  File "/home/airflow/.local/lib/python3.12/site-packages/sqlalchemy/engine/base.py", line 1770, in exec_driver_sql
    return self._exec_driver_sql(
           ^^^^^^^^^^^^^^^^^^^^^^
  File "/home/airflow/.local/lib/python3.12/site-packages/sqlalchemy/engine/base.py", line 1674, in _exec_driver_sql
    ret = self._execute_context(
          ^^^^^^^^^^^^^^^^^^^^^^
  File "/home/airflow/.local/lib/python3.12/site-packages/sqlalchemy/engine/base.py", line 1953, in _execute_context
    self._handle_dbapi_exception(
  File "/home/airflow/.local/lib/python3.12/site-packages/sqlalchemy/engine/base.py", line 2134, in _handle_dbapi_exception
    util.raise_(
  File "/home/airflow/.local/lib/python3.12/site-packages/sqlalchemy/util/compat.py", line 211, in raise_
    raise exception
  File "/home/airflow/.local/lib/python3.12/site-packages/sqlalchemy/engine/base.py", line 1910, in _execute_context
    self.dialect.do_execute(
  File "/home/airflow/.local/lib/python3.12/site-packages/sqlalchemy/engine/default.py", line 736, in do_execute
    cursor.execute(statement, parameters)
  File "/home/airflow/.local/lib/python3.12/site-packages/pymysql/cursors.py", line 153, in execute
    result = self._query(query)
             ^^^^^^^^^^^^^^^^^^
  File "/home/airflow/.local/lib/python3.12/site-packages/pymysql/cursors.py", line 322, in _query
    conn.query(q)
  File "/home/airflow/.local/lib/python3.12/site-packages/pymysql/connections.py", line 563, in query
    self._affected_rows = self._read_query_result(unbuffered=unbuffered)
                          ^^^^^^^^^^^^^^^^^^^^^^^^^^^^^^^^^^^^^^^^^^^^^^
  File "/home/airflow/.local/lib/python3.12/site-packages/pymysql/connections.py", line 825, in _read_query_result
    result.read()
  File "/home/airflow/.local/lib/python3.12/site-packages/pymysql/connections.py", line 1199, in read
    first_packet = self.connection._read_packet()
                   ^^^^^^^^^^^^^^^^^^^^^^^^^^^^^^
  File "/home/airflow/.local/lib/python3.12/site-packages/pymysql/connections.py", line 775, in _read_packet
    packet.raise_for_error()
  File "/home/airflow/.local/lib/python3.12/site-packages/pymysql/protocol.py", line 219, in raise_for_error
    err.raise_mysql_exception(self._data)
  File "/home/airflow/.local/lib/python3.12/site-packages/pymysql/err.py", line 150, in raise_mysql_exception
    raise errorclass(errno, errval)
sqlalchemy.exc.ProgrammingError: (pymysql.err.ProgrammingError) (1146, "Table 'eia.co2_emission' doesn't exist")
[SQL: SHOW CREATE TABLE `co2_emission`]
(Background on this error at: https://sqlalche.me/e/14/f405)

The above exception was the direct cause of the following exception:

Traceback (most recent call last):
  File "/home/airflow/.local/lib/python3.12/site-packages/airflow/models/taskinstance.py", line 767, in _execute_task
    result = _execute_callable(context=context, **execute_callable_kwargs)
             ^^^^^^^^^^^^^^^^^^^^^^^^^^^^^^^^^^^^^^^^^^^^^^^^^^^^^^^^^^^^^
  File "/home/airflow/.local/lib/python3.12/site-packages/airflow/models/taskinstance.py", line 733, in _execute_callable
    return ExecutionCallableRunner(
           ^^^^^^^^^^^^^^^^^^^^^^^^
  File "/home/airflow/.local/lib/python3.12/site-packages/airflow/utils/operator_helpers.py", line 252, in run
    return self.func(*args, **kwargs)
           ^^^^^^^^^^^^^^^^^^^^^^^^^^
  File "/home/airflow/.local/lib/python3.12/site-packages/airflow/models/baseoperator.py", line 406, in wrapper
    return func(self, *args, **kwargs)
           ^^^^^^^^^^^^^^^^^^^^^^^^^^^
  File "/home/airflow/.local/lib/python3.12/site-packages/airflow/operators/python.py", line 238, in execute
    return_value = self.execute_callable()
                   ^^^^^^^^^^^^^^^^^^^^^^^
  File "/home/airflow/.local/lib/python3.12/site-packages/airflow/operators/python.py", line 256, in execute_callable
    return runner.run(*self.op_args, **self.op_kwargs)
           ^^^^^^^^^^^^^^^^^^^^^^^^^^^^^^^^^^^^^^^^^^^
  File "/home/airflow/.local/lib/python3.12/site-packages/airflow/utils/operator_helpers.py", line 252, in run
    return self.func(*args, **kwargs)
           ^^^^^^^^^^^^^^^^^^^^^^^^^^
  File "/opt/airflow/dags/new_dag.py", line 113, in fetch_api1_data
    mysql_connect(data_api1, "co2_emission")
  File "/opt/airflow/dags/new_dag.py", line 68, in mysql_connect
    dataframe.to_sql(table_name, con=connection, if_exists='replace', index=False)
  File "/home/airflow/.local/lib/python3.12/site-packages/pandas/util/_decorators.py", line 333, in wrapper
    return func(*args, **kwargs)
           ^^^^^^^^^^^^^^^^^^^^^
  File "/home/airflow/.local/lib/python3.12/site-packages/pandas/core/generic.py", line 3008, in to_sql
    return sql.to_sql(
           ^^^^^^^^^^^
  File "/home/airflow/.local/lib/python3.12/site-packages/pandas/io/sql.py", line 788, in to_sql
    return pandas_sql.to_sql(
           ^^^^^^^^^^^^^^^^^^
  File "/home/airflow/.local/lib/python3.12/site-packages/pandas/io/sql.py", line 1948, in to_sql
    table = self.prep_table(
            ^^^^^^^^^^^^^^^^
  File "/home/airflow/.local/lib/python3.12/site-packages/pandas/io/sql.py", line 1852, in prep_table
    table.create()
  File "/home/airflow/.local/lib/python3.12/site-packages/pandas/io/sql.py", line 929, in create
    self.pd_sql.drop_table(self.name, self.schema)
  File "/home/airflow/.local/lib/python3.12/site-packages/pandas/io/sql.py", line 1999, in drop_table
    self.meta.reflect(
  File "/home/airflow/.local/lib/python3.12/site-packages/sqlalchemy/sql/schema.py", line 4901, in reflect
    Table(name, self, **reflect_opts)
  File "<string>", line 2, in __new__
  File "/home/airflow/.local/lib/python3.12/site-packages/sqlalchemy/util/deprecations.py", line 375, in warned
    return fn(*args, **kwargs)
           ^^^^^^^^^^^^^^^^^^^
  File "/home/airflow/.local/lib/python3.12/site-packages/sqlalchemy/sql/schema.py", line 618, in __new__
    with util.safe_reraise():
  File "/home/airflow/.local/lib/python3.12/site-packages/sqlalchemy/util/langhelpers.py", line 70, in __exit__
    compat.raise_(
  File "/home/airflow/.local/lib/python3.12/site-packages/sqlalchemy/util/compat.py", line 211, in raise_
    raise exception
  File "/home/airflow/.local/lib/python3.12/site-packages/sqlalchemy/sql/schema.py", line 614, in __new__
    table._init(name, metadata, *args, **kw)
  File "/home/airflow/.local/lib/python3.12/site-packages/sqlalchemy/sql/schema.py", line 689, in _init
    self._autoload(
  File "/home/airflow/.local/lib/python3.12/site-packages/sqlalchemy/sql/schema.py", line 724, in _autoload
    conn_insp.reflect_table(
  File "/home/airflow/.local/lib/python3.12/site-packages/sqlalchemy/engine/reflection.py", line 757, in reflect_table
    tbl_opts = self.get_table_options(
               ^^^^^^^^^^^^^^^^^^^^^^^
  File "/home/airflow/.local/lib/python3.12/site-packages/sqlalchemy/engine/reflection.py", line 398, in get_table_options
    return self.dialect.get_table_options(
           ^^^^^^^^^^^^^^^^^^^^^^^^^^^^^^^
  File "<string>", line 2, in get_table_options
  File "/home/airflow/.local/lib/python3.12/site-packages/sqlalchemy/engine/reflection.py", line 55, in cache
    ret = fn(self, con, *args, **kw)
          ^^^^^^^^^^^^^^^^^^^^^^^^^^
  File "/home/airflow/.local/lib/python3.12/site-packages/sqlalchemy/dialects/mysql/base.py", line 2828, in get_table_options
    parsed_state = self._parsed_state_or_create(
                   ^^^^^^^^^^^^^^^^^^^^^^^^^^^^^
  File "/home/airflow/.local/lib/python3.12/site-packages/sqlalchemy/dialects/mysql/base.py", line 3085, in _parsed_state_or_create
    return self._setup_parser(
           ^^^^^^^^^^^^^^^^^^^
  File "<string>", line 2, in _setup_parser
  File "/home/airflow/.local/lib/python3.12/site-packages/sqlalchemy/engine/reflection.py", line 55, in cache
    ret = fn(self, con, *args, **kw)
          ^^^^^^^^^^^^^^^^^^^^^^^^^^
  File "/home/airflow/.local/lib/python3.12/site-packages/sqlalchemy/dialects/mysql/base.py", line 3112, in _setup_parser
    sql = self._show_create_table(
          ^^^^^^^^^^^^^^^^^^^^^^^^
  File "/home/airflow/.local/lib/python3.12/site-packages/sqlalchemy/dialects/mysql/base.py", line 3223, in _show_create_table
    util.raise_(exc.NoSuchTableError(full_name), replace_context=e)
  File "/home/airflow/.local/lib/python3.12/site-packages/sqlalchemy/util/compat.py", line 211, in raise_
    raise exception
sqlalchemy.exc.NoSuchTableError: `co2_emission`
[2024-10-14T05:10:51.243+0000] {logging_mixin.py:190} INFO - Task instance in failure state
[2024-10-14T05:10:51.245+0000] {logging_mixin.py:190} INFO - Task start:2024-10-14 05:10:38.751645+00:00 end:2024-10-14 05:10:51.240984+00:00 duration:12.489339
[2024-10-14T05:10:51.246+0000] {logging_mixin.py:190} INFO - Task:<Task(PythonOperator): fetch_api1_data> dag:<DAG: eia_data_pipeline> dagrun:<DagRun eia_data_pipeline @ 2024-10-13 00:00:00+00:00: scheduled__2024-10-13T00:00:00+00:00, state:running, queued_at: 2024-10-14 05:10:01.946185+00:00. externally triggered: False>
[2024-10-14T05:10:51.248+0000] {logging_mixin.py:190} INFO - Failure caused by `co2_emission`
[2024-10-14T05:10:51.249+0000] {taskinstance.py:1225} INFO - Marking task as UP_FOR_RETRY. dag_id=eia_data_pipeline, task_id=fetch_api1_data, run_id=scheduled__2024-10-13T00:00:00+00:00, execution_date=20241013T000000, start_date=20241014T051038, end_date=20241014T051051
[2024-10-14T05:10:51.308+0000] {taskinstance.py:340} INFO - ::group::Post task execution logs
[2024-10-14T05:10:51.311+0000] {standard_task_runner.py:124} ERROR - Failed to execute job 35 for task fetch_api1_data (`co2_emission`; 107)
Traceback (most recent call last):
  File "/home/airflow/.local/lib/python3.12/site-packages/sqlalchemy/engine/base.py", line 1910, in _execute_context
    self.dialect.do_execute(
  File "/home/airflow/.local/lib/python3.12/site-packages/sqlalchemy/engine/default.py", line 736, in do_execute
    cursor.execute(statement, parameters)
  File "/home/airflow/.local/lib/python3.12/site-packages/pymysql/cursors.py", line 153, in execute
    result = self._query(query)
             ^^^^^^^^^^^^^^^^^^
  File "/home/airflow/.local/lib/python3.12/site-packages/pymysql/cursors.py", line 322, in _query
    conn.query(q)
  File "/home/airflow/.local/lib/python3.12/site-packages/pymysql/connections.py", line 563, in query
    self._affected_rows = self._read_query_result(unbuffered=unbuffered)
                          ^^^^^^^^^^^^^^^^^^^^^^^^^^^^^^^^^^^^^^^^^^^^^^
  File "/home/airflow/.local/lib/python3.12/site-packages/pymysql/connections.py", line 825, in _read_query_result
    result.read()
  File "/home/airflow/.local/lib/python3.12/site-packages/pymysql/connections.py", line 1199, in read
    first_packet = self.connection._read_packet()
                   ^^^^^^^^^^^^^^^^^^^^^^^^^^^^^^
  File "/home/airflow/.local/lib/python3.12/site-packages/pymysql/connections.py", line 775, in _read_packet
    packet.raise_for_error()
  File "/home/airflow/.local/lib/python3.12/site-packages/pymysql/protocol.py", line 219, in raise_for_error
    err.raise_mysql_exception(self._data)
  File "/home/airflow/.local/lib/python3.12/site-packages/pymysql/err.py", line 150, in raise_mysql_exception
    raise errorclass(errno, errval)
pymysql.err.ProgrammingError: (1146, "Table 'eia.co2_emission' doesn't exist")

The above exception was the direct cause of the following exception:

Traceback (most recent call last):
  File "/home/airflow/.local/lib/python3.12/site-packages/sqlalchemy/dialects/mysql/base.py", line 3220, in _show_create_table
    ).exec_driver_sql(st)
      ^^^^^^^^^^^^^^^^^^^
  File "/home/airflow/.local/lib/python3.12/site-packages/sqlalchemy/engine/base.py", line 1770, in exec_driver_sql
    return self._exec_driver_sql(
           ^^^^^^^^^^^^^^^^^^^^^^
  File "/home/airflow/.local/lib/python3.12/site-packages/sqlalchemy/engine/base.py", line 1674, in _exec_driver_sql
    ret = self._execute_context(
          ^^^^^^^^^^^^^^^^^^^^^^
  File "/home/airflow/.local/lib/python3.12/site-packages/sqlalchemy/engine/base.py", line 1953, in _execute_context
    self._handle_dbapi_exception(
  File "/home/airflow/.local/lib/python3.12/site-packages/sqlalchemy/engine/base.py", line 2134, in _handle_dbapi_exception
    util.raise_(
  File "/home/airflow/.local/lib/python3.12/site-packages/sqlalchemy/util/compat.py", line 211, in raise_
    raise exception
  File "/home/airflow/.local/lib/python3.12/site-packages/sqlalchemy/engine/base.py", line 1910, in _execute_context
    self.dialect.do_execute(
  File "/home/airflow/.local/lib/python3.12/site-packages/sqlalchemy/engine/default.py", line 736, in do_execute
    cursor.execute(statement, parameters)
  File "/home/airflow/.local/lib/python3.12/site-packages/pymysql/cursors.py", line 153, in execute
    result = self._query(query)
             ^^^^^^^^^^^^^^^^^^
  File "/home/airflow/.local/lib/python3.12/site-packages/pymysql/cursors.py", line 322, in _query
    conn.query(q)
  File "/home/airflow/.local/lib/python3.12/site-packages/pymysql/connections.py", line 563, in query
    self._affected_rows = self._read_query_result(unbuffered=unbuffered)
                          ^^^^^^^^^^^^^^^^^^^^^^^^^^^^^^^^^^^^^^^^^^^^^^
  File "/home/airflow/.local/lib/python3.12/site-packages/pymysql/connections.py", line 825, in _read_query_result
    result.read()
  File "/home/airflow/.local/lib/python3.12/site-packages/pymysql/connections.py", line 1199, in read
    first_packet = self.connection._read_packet()
                   ^^^^^^^^^^^^^^^^^^^^^^^^^^^^^^
  File "/home/airflow/.local/lib/python3.12/site-packages/pymysql/connections.py", line 775, in _read_packet
    packet.raise_for_error()
  File "/home/airflow/.local/lib/python3.12/site-packages/pymysql/protocol.py", line 219, in raise_for_error
    err.raise_mysql_exception(self._data)
  File "/home/airflow/.local/lib/python3.12/site-packages/pymysql/err.py", line 150, in raise_mysql_exception
    raise errorclass(errno, errval)
sqlalchemy.exc.ProgrammingError: (pymysql.err.ProgrammingError) (1146, "Table 'eia.co2_emission' doesn't exist")
[SQL: SHOW CREATE TABLE `co2_emission`]
(Background on this error at: https://sqlalche.me/e/14/f405)

The above exception was the direct cause of the following exception:

Traceback (most recent call last):
  File "/home/airflow/.local/lib/python3.12/site-packages/airflow/task/task_runner/standard_task_runner.py", line 117, in _start_by_fork
    ret = args.func(args, dag=self.dag)
          ^^^^^^^^^^^^^^^^^^^^^^^^^^^^^
  File "/home/airflow/.local/lib/python3.12/site-packages/airflow/cli/cli_config.py", line 49, in command
    return func(*args, **kwargs)
           ^^^^^^^^^^^^^^^^^^^^^
  File "/home/airflow/.local/lib/python3.12/site-packages/airflow/utils/cli.py", line 115, in wrapper
    return f(*args, **kwargs)
           ^^^^^^^^^^^^^^^^^^
  File "/home/airflow/.local/lib/python3.12/site-packages/airflow/cli/commands/task_command.py", line 483, in task_run
    task_return_code = _run_task_by_selected_method(args, _dag, ti)
                       ^^^^^^^^^^^^^^^^^^^^^^^^^^^^^^^^^^^^^^^^^^^^
  File "/home/airflow/.local/lib/python3.12/site-packages/airflow/cli/commands/task_command.py", line 256, in _run_task_by_selected_method
    return _run_raw_task(args, ti)
           ^^^^^^^^^^^^^^^^^^^^^^^
  File "/home/airflow/.local/lib/python3.12/site-packages/airflow/cli/commands/task_command.py", line 341, in _run_raw_task
    return ti._run_raw_task(
           ^^^^^^^^^^^^^^^^^
  File "/home/airflow/.local/lib/python3.12/site-packages/airflow/utils/session.py", line 97, in wrapper
    return func(*args, session=session, **kwargs)
           ^^^^^^^^^^^^^^^^^^^^^^^^^^^^^^^^^^^^^^
  File "/home/airflow/.local/lib/python3.12/site-packages/airflow/models/taskinstance.py", line 3004, in _run_raw_task
    return _run_raw_task(
           ^^^^^^^^^^^^^^
  File "/home/airflow/.local/lib/python3.12/site-packages/airflow/models/taskinstance.py", line 273, in _run_raw_task
    TaskInstance._execute_task_with_callbacks(
  File "/home/airflow/.local/lib/python3.12/site-packages/airflow/models/taskinstance.py", line 3158, in _execute_task_with_callbacks
    result = self._execute_task(context, task_orig)
             ^^^^^^^^^^^^^^^^^^^^^^^^^^^^^^^^^^^^^^
  File "/home/airflow/.local/lib/python3.12/site-packages/airflow/models/taskinstance.py", line 3182, in _execute_task
    return _execute_task(self, context, task_orig)
           ^^^^^^^^^^^^^^^^^^^^^^^^^^^^^^^^^^^^^^^
  File "/home/airflow/.local/lib/python3.12/site-packages/airflow/models/taskinstance.py", line 767, in _execute_task
    result = _execute_callable(context=context, **execute_callable_kwargs)
             ^^^^^^^^^^^^^^^^^^^^^^^^^^^^^^^^^^^^^^^^^^^^^^^^^^^^^^^^^^^^^
  File "/home/airflow/.local/lib/python3.12/site-packages/airflow/models/taskinstance.py", line 733, in _execute_callable
    return ExecutionCallableRunner(
           ^^^^^^^^^^^^^^^^^^^^^^^^
  File "/home/airflow/.local/lib/python3.12/site-packages/airflow/utils/operator_helpers.py", line 252, in run
    return self.func(*args, **kwargs)
           ^^^^^^^^^^^^^^^^^^^^^^^^^^
  File "/home/airflow/.local/lib/python3.12/site-packages/airflow/models/baseoperator.py", line 406, in wrapper
    return func(self, *args, **kwargs)
           ^^^^^^^^^^^^^^^^^^^^^^^^^^^
  File "/home/airflow/.local/lib/python3.12/site-packages/airflow/operators/python.py", line 238, in execute
    return_value = self.execute_callable()
                   ^^^^^^^^^^^^^^^^^^^^^^^
  File "/home/airflow/.local/lib/python3.12/site-packages/airflow/operators/python.py", line 256, in execute_callable
    return runner.run(*self.op_args, **self.op_kwargs)
           ^^^^^^^^^^^^^^^^^^^^^^^^^^^^^^^^^^^^^^^^^^^
  File "/home/airflow/.local/lib/python3.12/site-packages/airflow/utils/operator_helpers.py", line 252, in run
    return self.func(*args, **kwargs)
           ^^^^^^^^^^^^^^^^^^^^^^^^^^
  File "/opt/airflow/dags/new_dag.py", line 113, in fetch_api1_data
    mysql_connect(data_api1, "co2_emission")
  File "/opt/airflow/dags/new_dag.py", line 68, in mysql_connect
    dataframe.to_sql(table_name, con=connection, if_exists='replace', index=False)
  File "/home/airflow/.local/lib/python3.12/site-packages/pandas/util/_decorators.py", line 333, in wrapper
    return func(*args, **kwargs)
           ^^^^^^^^^^^^^^^^^^^^^
  File "/home/airflow/.local/lib/python3.12/site-packages/pandas/core/generic.py", line 3008, in to_sql
    return sql.to_sql(
           ^^^^^^^^^^^
  File "/home/airflow/.local/lib/python3.12/site-packages/pandas/io/sql.py", line 788, in to_sql
    return pandas_sql.to_sql(
           ^^^^^^^^^^^^^^^^^^
  File "/home/airflow/.local/lib/python3.12/site-packages/pandas/io/sql.py", line 1948, in to_sql
    table = self.prep_table(
            ^^^^^^^^^^^^^^^^
  File "/home/airflow/.local/lib/python3.12/site-packages/pandas/io/sql.py", line 1852, in prep_table
    table.create()
  File "/home/airflow/.local/lib/python3.12/site-packages/pandas/io/sql.py", line 929, in create
    self.pd_sql.drop_table(self.name, self.schema)
  File "/home/airflow/.local/lib/python3.12/site-packages/pandas/io/sql.py", line 1999, in drop_table
    self.meta.reflect(
  File "/home/airflow/.local/lib/python3.12/site-packages/sqlalchemy/sql/schema.py", line 4901, in reflect
    Table(name, self, **reflect_opts)
  File "<string>", line 2, in __new__
  File "/home/airflow/.local/lib/python3.12/site-packages/sqlalchemy/util/deprecations.py", line 375, in warned
    return fn(*args, **kwargs)
           ^^^^^^^^^^^^^^^^^^^
  File "/home/airflow/.local/lib/python3.12/site-packages/sqlalchemy/sql/schema.py", line 618, in __new__
    with util.safe_reraise():
  File "/home/airflow/.local/lib/python3.12/site-packages/sqlalchemy/util/langhelpers.py", line 70, in __exit__
    compat.raise_(
  File "/home/airflow/.local/lib/python3.12/site-packages/sqlalchemy/util/compat.py", line 211, in raise_
    raise exception
  File "/home/airflow/.local/lib/python3.12/site-packages/sqlalchemy/sql/schema.py", line 614, in __new__
    table._init(name, metadata, *args, **kw)
  File "/home/airflow/.local/lib/python3.12/site-packages/sqlalchemy/sql/schema.py", line 689, in _init
    self._autoload(
  File "/home/airflow/.local/lib/python3.12/site-packages/sqlalchemy/sql/schema.py", line 724, in _autoload
    conn_insp.reflect_table(
  File "/home/airflow/.local/lib/python3.12/site-packages/sqlalchemy/engine/reflection.py", line 757, in reflect_table
    tbl_opts = self.get_table_options(
               ^^^^^^^^^^^^^^^^^^^^^^^
  File "/home/airflow/.local/lib/python3.12/site-packages/sqlalchemy/engine/reflection.py", line 398, in get_table_options
    return self.dialect.get_table_options(
           ^^^^^^^^^^^^^^^^^^^^^^^^^^^^^^^
  File "<string>", line 2, in get_table_options
  File "/home/airflow/.local/lib/python3.12/site-packages/sqlalchemy/engine/reflection.py", line 55, in cache
    ret = fn(self, con, *args, **kw)
          ^^^^^^^^^^^^^^^^^^^^^^^^^^
  File "/home/airflow/.local/lib/python3.12/site-packages/sqlalchemy/dialects/mysql/base.py", line 2828, in get_table_options
    parsed_state = self._parsed_state_or_create(
                   ^^^^^^^^^^^^^^^^^^^^^^^^^^^^^
  File "/home/airflow/.local/lib/python3.12/site-packages/sqlalchemy/dialects/mysql/base.py", line 3085, in _parsed_state_or_create
    return self._setup_parser(
           ^^^^^^^^^^^^^^^^^^^
  File "<string>", line 2, in _setup_parser
  File "/home/airflow/.local/lib/python3.12/site-packages/sqlalchemy/engine/reflection.py", line 55, in cache
    ret = fn(self, con, *args, **kw)
          ^^^^^^^^^^^^^^^^^^^^^^^^^^
  File "/home/airflow/.local/lib/python3.12/site-packages/sqlalchemy/dialects/mysql/base.py", line 3112, in _setup_parser
    sql = self._show_create_table(
          ^^^^^^^^^^^^^^^^^^^^^^^^
  File "/home/airflow/.local/lib/python3.12/site-packages/sqlalchemy/dialects/mysql/base.py", line 3223, in _show_create_table
    util.raise_(exc.NoSuchTableError(full_name), replace_context=e)
  File "/home/airflow/.local/lib/python3.12/site-packages/sqlalchemy/util/compat.py", line 211, in raise_
    raise exception
sqlalchemy.exc.NoSuchTableError: `co2_emission`
[2024-10-14T05:10:51.407+0000] {local_task_job_runner.py:266} INFO - Task exited with return code 1
[2024-10-14T05:10:51.473+0000] {taskinstance.py:3900} INFO - 0 downstream tasks scheduled from follow-on schedule check
[2024-10-14T05:10:51.480+0000] {local_task_job_runner.py:245} INFO - ::endgroup::
